File: data/data_piroliz_10/ExpDat_6.06.2022 Солома 29-1000 10 Ar +MS SCB.txt
#EXPORTTYPE:DATA ALL
#FILE:6.06.2022 Ñîëîìà 29-1000 10 Ar +MS SCB.ngb-ds5
#FORMAT:NETZSCH5
#FTYPE:ANSI
#IDENTITY:06.06.2022
#DECIMAL:COMMA
#SEPARATOR:SEMICOLON
#MTYPE:DSC
#INSTRUMENT:NETZSCH STA 449F5
#PROJECT:ÑÂ×
#DATE/TIME:06.06.2022 16:28
#CORR. FILE:Êîððåêöèÿ 2 26 -1000 10 Ar (50 ml-min) .ngb-bs5
#TEMPCAL:TCALZERO.TCX
#SENSITIVITY:SENSZERO.EXX
#LABORATORY:108
#OPERATOR:Èáðàåâà
#REMARK:
#SAMPLE:Ñîëîìà
#SAMPLE MASS /mg:5,01
#MATERIAL:
#REFERENCE:
#REFERENCE MASS /mg:0
#TYPE OF CRUCIBLE:Al2O3 85 µl, with lid
#SAMPLE CRUCIBLE MASS /mg:228,54
#REFERENCE CRUCIBLE MASS /mg:224,00
#PURGE 1 MFC:OXYGEN,252,5 ml/min
#PURGE 2 MFC:ARGON,240,3 ml/min
#PROTECTIVE MFC:ARGON,240,3 ml/min
#DSC RANGE /µV:5000
#TG RANGE /mg:35000
#TAU-R:---
#CORR. CODE:020
#EXO:+1
#RANGE:28°C/10,0(K/min)/1000°C
#SEGMENT:S1/1
#SEG. 1:28°C/10,0(K/min)/1000°C

##Temp./°C;Time/min;DSC/(uV/mg);Mass/%;QMID(s:1|m:2)/A;QMID(s:1|m:16)/A;QMID(s:1|m:28)/A;QMID(s:1|m:44)/A;QMID(s:1|m:18)/A;Sensit./(uV/mW)
 30,00000; 1,67154;3,696862e-02;99,94304;4,068099e-11;2,242491e-10;2,219227e-10;2,565550e-10;9,733553e-09;1,00000
 40,00000; 3,43621;     0,16064;99,81590;4,120875e-11;2,252562e-10;2,242056e-10;2,572958e-10;9,716705e-09;1,00000
 50,00000; 4,50669;     0,24869;99,85756;4,124482e-11;2,253695e-10;2,248602e-10;2,570556e-10;9,715338e-09;1,00000
 60,00000; 5,41093;     0,34179;99,81549;4,151777e-11;2,250848e-10;2,248202e-10;2,568322e-10;9,714387e-09;1,00000
 70,00000; 6,23115;     0,44905;99,74527;4,179247e-11;2,254544e-10;2,242587e-10;2,565794e-10;9,714392e-09;1,00000
 80,00000; 7,00994;     0,54106;99,63979;4,189964e-11;2,254421e-10;2,241163e-10;2,564352e-10;9,716496e-09;1,00000
 90,00000; 7,76526;     0,62254;99,57094;4,185473e-11;2,251185e-10;2,237376e-10;2,563026e-10;9,719063e-09;1,00000
100,00000; 8,51529;     0,70103;99,41606;4,181968e-11;2,247813e-10;2,236040e-10;2,558621e-10;9,719120e-09;1,00000
110,00000; 9,27448;     0,80139;99,31560;4,192106e-11;2,251948e-10;2,233798e-10;2,557422e-10;9,713373e-09;1,00000
120,00000;10,05182;     0,91788;99,18722;4,208454e-11;2,256592e-10;2,231219e-10;2,560506e-10;9,700373e-09;1,00000
130,00000;10,84731;     1,03880;99,10584;4,227011e-11;2,251306e-10;2,232416e-10;2,564682e-10;9,681715e-09;1,00000
140,00000;11,66258;     1,15868;99,03121;4,249505e-11;2,244633e-10;2,234513e-10;2,568674e-10;9,660977e-09;1,00000
150,00000;12,50404;     1,27256;98,99747;4,247342e-11;2,240942e-10;2,242312e-10;2,579316e-10;9,641809e-09;1,00000
160,00000;13,37787;     1,38184;98,94731;4,227336e-11;2,238872e-10;2,245912e-10;2,596508e-10;9,626504e-09;1,00000
170,00000;14,28368;     1,49809;98,85966;4,228370e-11;2,243001e-10;2,240553e-10;2,614333e-10;9,615670e-09;1,00000
180,00000;15,21663;     1,62729;98,66851;4,235839e-11;2,245922e-10;2,240774e-10;2,637363e-10;9,609051e-09;1,00000
190,00000;16,17195;     1,75538;98,46307;4,265916e-11;2,243753e-10;2,244472e-10;2,667511e-10;9,606655e-09;1,00000
200,00000;17,14793;     1,89062;98,06630;4,289553e-11;2,248585e-10;2,256393e-10;2,721300e-10;9,610029e-09;1,00000
210,00000;18,13832;     2,02857;97,53614;4,290546e-11;2,263737e-10;2,278513e-10;2,809272e-10;9,621768e-09;1,00000
220,00000;19,14243;     2,17972;96,77038;4,308923e-11;2,281316e-10;2,314412e-10;2,941596e-10;9,642634e-09;1,00000
230,00000;20,15203;     2,34214;95,75217;4,332325e-11;2,306724e-10;2,367453e-10;3,093020e-10;9,671579e-09;1,00000
240,00000;21,16567;     2,50660;94,48905;4,354339e-11;2,334073e-10;2,444610e-10;3,253851e-10;9,708097e-09;1,00000
250,00000;22,18027;     2,68024;92,99107;4,400975e-11;2,369455e-10;2,545268e-10;3,449199e-10;9,753612e-09;1,00000
260,00000;23,19477;     2,85192;91,10617;4,442713e-11;2,407319e-10;2,685034e-10;3,713715e-10;9,810576e-09;1,00000
270,00000;24,20821;     3,02558;88,74034;4,492719e-11;2,462913e-10;2,874493e-10;4,040732e-10;9,879346e-09;1,00000
280,00000;25,22041;     3,18973;86,09252;4,557272e-11;2,523492e-10;3,103118e-10;4,399640e-10;9,956720e-09;1,00000
290,00000;26,23508;     3,33350;82,68994;4,614667e-11;2,589172e-10;3,366319e-10;4,781780e-10;1,003978e-08;1,00000
300,00000;27,24831;     3,44861;78,91210;4,672371e-11;2,649610e-10;3,655222e-10;5,143842e-10;1,013132e-08;1,00000
310,00000;28,26038;     3,53713;74,44336;4,743843e-11;2,714186e-10;3,993019e-10;5,528577e-10;1,024218e-08;1,00000
320,00000;29,27085;     3,60790;69,02478;4,838138e-11;2,794287e-10;4,466065e-10;6,071454e-10;1,037354e-08;1,00000
330,00000;30,28121;     3,64183;62,34949;4,948158e-11;2,881293e-10;5,010876e-10;6,746240e-10;1,048810e-08;1,00000
340,00000;31,29157;     3,61751;55,22390;5,032232e-11;2,925915e-10;5,209479e-10;7,072025e-10;1,051306e-08;1,00000
350,00000;32,30272;     3,54119;49,94379;5,009680e-11;2,830775e-10;4,701407e-10;6,465036e-10;1,040626e-08;1,00000
360,00000;33,31448;     3,50413;46,66590;4,903627e-11;2,668926e-10;3,941033e-10;5,396423e-10;1,021118e-08;1,00000
370,00000;34,32450;     3,53299;44,88246;4,824065e-11;2,549674e-10;3,383482e-10;4,564195e-10;1,001290e-08;1,00000
380,00000;35,33292;     3,58980;43,64228;4,764549e-11;2,491245e-10;3,063450e-10;4,058130e-10;9,864082e-09;1,00000
390,00000;36,34040;     3,66036;42,60942;4,709515e-11;2,487096e-10;2,931082e-10;3,812442e-10;9,770553e-09;1,00000
400,00000;37,34723;     3,72633;41,55235;4,680153e-11;2,495745e-10;2,893556e-10;3,691253e-10;9,714900e-09;1,00000
410,00000;38,35371;     3,78823;40,63742;4,645593e-11;2,497749e-10;2,885237e-10;3,599821e-10;9,678268e-09;1,00000
420,00000;39,36004;     3,83876;39,70225;4,610660e-11;2,491725e-10;2,886698e-10;3,518842e-10;9,648439e-09;1,00000
430,00000;40,36519;     3,88351;38,87390;4,628153e-11;2,477539e-10;2,885749e-10;3,448744e-10;9,619390e-09;1,00000
440,00000;41,37055;     3,92938;38,12936;4,661168e-11;2,464375e-10;2,885913e-10;3,381751e-10;9,589642e-09;1,00000
450,00000;42,37502;     3,97612;37,42330;4,645328e-11;2,448239e-10;2,876057e-10;3,314918e-10;9,559667e-09;1,00000
460,00000;43,38055;     4,01955;36,79013;4,636911e-11;2,444466e-10;2,861226e-10;3,263827e-10;9,529902e-09;1,00000
470,00000;44,38357;     4,05063;36,26926;4,633726e-11;2,447884e-10;2,843777e-10;3,220481e-10;9,500680e-09;1,00000
480,00000;45,38601;     4,08384;35,75378;4,637097e-11;2,453198e-10;2,826864e-10;3,180204e-10;9,472835e-09;1,00000
490,00000;46,38765;     4,08973;35,35732;4,655396e-11;2,461314e-10;2,781351e-10;3,167616e-10;9,445802e-09;1,00000
500,00000;47,38907;     4,08671;34,98203;4,653051e-11;2,464818e-10;2,682481e-10;3,191675e-10;9,418682e-09;1,00000
510,00000;48,39087;     4,09540;34,64989;4,650908e-11;2,463913e-10;2,599042e-10;3,207687e-10;9,392169e-09;1,00000
520,00000;49,39157;     4,10997;34,35661;4,643682e-11;2,455055e-10;2,544697e-10;3,197683e-10;9,367132e-09;1,00000
530,00000;50,39209;     4,10537;34,14955;4,641218e-11;2,440788e-10;2,502215e-10;3,178987e-10;9,343251e-09;1,00000
540,00000;51,39266;     4,08721;33,89075;4,644283e-11;2,424541e-10;2,480965e-10;3,154343e-10;9,319831e-09;1,00000
550,00000;52,39164;     4,04892;33,67502;4,653348e-11;2,401414e-10;2,469129e-10;3,121111e-10;9,296949e-09;1,00000
560,00000;53,39173;     3,99135;33,48481;4,669523e-11;2,372189e-10;2,458645e-10;3,080495e-10;9,275470e-09;1,00000
570,00000;54,39079;     3,92052;33,28018;4,661304e-11;2,348359e-10;2,446438e-10;3,033720e-10;9,255887e-09;1,00000
580,00000;55,38975;     3,85386;33,15750;4,677185e-11;2,325277e-10;2,439380e-10;2,989641e-10;9,237414e-09;1,00000
590,00000;56,38925;     3,79445;32,93291;4,703577e-11;2,301105e-10;2,443618e-10;2,942741e-10;9,219540e-09;1,00000
600,00000;57,38942;     3,74781;32,81522;4,754743e-11;2,280292e-10;2,463821e-10;2,885910e-10;9,202572e-09;1,00000
610,00000;58,38983;     3,71876;32,66222;4,804093e-11;2,258043e-10;2,489445e-10;2,836678e-10;9,186096e-09;1,00000
620,00000;59,39012;     3,70671;32,53457;4,907630e-11;2,235230e-10;2,508529e-10;2,809632e-10;9,169007e-09;1,00000
630,00000;60,39091;     3,72515;32,41669;5,037041e-11;2,216964e-10;2,517611e-10;2,806145e-10;9,150920e-09;1,00000
640,00000;61,39150;     3,77648;32,26316;5,152663e-11;2,196643e-10;2,526545e-10;2,798586e-10;9,132744e-09;1,00000
650,00000;62,39363;     3,85804;32,13494;5,284797e-11;2,176967e-10;2,540732e-10;2,774793e-10;9,114966e-09;1,00000
660,00000;63,39606;     3,97139;32,03007;5,400769e-11;2,161961e-10;2,553875e-10;2,753256e-10;9,096956e-09;1,00000
670,00000;64,39876;     4,11292;31,92049;5,518371e-11;2,150756e-10;2,562027e-10;2,727476e-10;9,078663e-09;1,00000
680,00000;65,40260;     4,25883;31,80695;5,585308e-11;2,135851e-10;2,563334e-10;2,702053e-10;9,060871e-09;1,00000
690,00000;66,40588;     4,41302;31,74702;5,652282e-11;2,120640e-10;2,565206e-10;2,685672e-10;9,044333e-09;1,00000
700,00000;67,40901;     4,55980;31,66125;5,706370e-11;2,110807e-10;2,568709e-10;2,673033e-10;9,028890e-09;1,00000
710,00000;68,41291;     4,72070;31,58141;5,683407e-11;2,100226e-10;2,567761e-10;2,663901e-10;9,013623e-09;1,00000
720,00000;69,41532;     4,87562;31,51706;5,647072e-11;2,096367e-10;2,566423e-10;2,658983e-10;8,997808e-09;1,00000
730,00000;70,41918;     5,02494;31,42353;5,609545e-11;2,093145e-10;2,557345e-10;2,651097e-10;8,981085e-09;1,00000
740,00000;71,42065;     5,17473;31,37088;5,578583e-11;2,088723e-10;2,545131e-10;2,646113e-10;8,964617e-09;1,00000
750,00000;72,42279;     5,31721;31,28632;5,524179e-11;2,083232e-10;2,532492e-10;2,640214e-10;8,949802e-09;1,00000
760,00000;73,42430;     5,46006;31,20648;5,413684e-11;2,081294e-10;2,519761e-10;2,633949e-10;8,934960e-09;1,00000
770,00000;74,42597;     5,61012;31,08975;5,312850e-11;2,078387e-10;2,501335e-10;2,633274e-10;8,918804e-09;1,00000
780,00000;75,42699;     5,76532;31,10289;5,217509e-11;2,075875e-10;2,482113e-10;2,637384e-10;8,902371e-09;1,00000
790,00000;76,42873;     5,93787;31,06264;5,136495e-11;2,069344e-10;2,462767e-10;2,648181e-10;8,885876e-09;1,00000
800,00000;77,43007;     6,09669;30,95525;5,042243e-11;2,065786e-10;2,443201e-10;2,659664e-10;8,869307e-09;1,00000
810,00000;78,43144;     6,27114;31,03914;4,940863e-11;2,062673e-10;2,422810e-10;2,666900e-10;8,852962e-09;1,00000
820,00000;79,43321;     6,45055;30,92557;4,869929e-11;2,061962e-10;2,395348e-10;2,687550e-10;8,836009e-09;1,00000
830,00000;80,43397;     6,65746;30,88792;4,824224e-11;2,062938e-10;2,358239e-10;2,720243e-10;8,817912e-09;1,00000
840,00000;81,43603;     6,93674;30,86695;4,781026e-11;2,062895e-10;2,327366e-10;2,744358e-10;8,799651e-09;1,00000
850,00000;82,43844;     7,26137;30,78151;4,750868e-11;2,059670e-10;2,303355e-10;2,753264e-10;8,782331e-09;1,00000
860,00000;83,43967;     7,59878;30,80033;4,735575e-11;2,054868e-10;2,287580e-10;2,757207e-10;8,766477e-09;1,00000
870,00000;84,43897;     7,83623;30,75174;4,702878e-11;2,050739e-10;2,277853e-10;2,754458e-10;8,751395e-09;1,00000
880,00000;85,43516;     7,93105;30,74424;4,691401e-11;2,050643e-10;2,269491e-10;2,747622e-10;8,735979e-09;1,00000
890,00000;86,42825;     7,90001;30,64468;4,690473e-11;2,052526e-10;2,261688e-10;2,743976e-10;8,720421e-09;1,00000
900,00000;87,41843;     7,74953;30,70941;4,694529e-11;2,047632e-10;2,262339e-10;2,741265e-10;8,704767e-09;1,00000
910,00000;88,40946;     7,48304;30,60644;4,691376e-11;2,044982e-10;2,265435e-10;2,736335e-10;8,688878e-09;1,00000
920,00000;89,40100;     7,16411;30,64860;4,684449e-11;2,043359e-10;2,261866e-10;2,730389e-10;8,673490e-09;1,00000
930,00000;90,39476;     6,87168;30,54244;4,687233e-11;2,041364e-10;2,261341e-10;2,722182e-10;8,658190e-09;1,00000
940,00000;91,38870;     6,61755;30,52498;4,678263e-11;2,037152e-10;2,257859e-10;2,721656e-10;8,641531e-09;1,00000
950,00000;92,38397;     6,38840;30,51579;4,696962e-11;2,036324e-10;2,255857e-10;2,718858e-10;8,623955e-09;1,00000
960,00000;93,37993;     6,20874;30,46591;4,688003e-11;2,034698e-10;2,259857e-10;2,717451e-10;8,607256e-09;1,00000
970,00000;94,37772;     6,04096;30,50179;4,685651e-11;2,033388e-10;2,264364e-10;2,715034e-10;8,591857e-09;1,00000
980,00000;95,37496;     5,88865;30,39266;4,693256e-11;2,032483e-10;2,264985e-10;2,715547e-10;8,578274e-09;1,00000
990,00000;96,37196;     5,72398;30,44482;4,666610e-11;2,024740e-10;2,264563e-10;2,712653e-10;8,567044e-09;1,00000