File: data/data_piroliz_10/ExpDat_31.05.2022 Отруби  27-1000 10 Ar +MS SCB.txt
#EXPORTTYPE:DATA ALL
#FILE:31.05.2022 Îòðóáè  27-1000 10 Ar +MS SCB .ngb-ds5
#FORMAT:NETZSCH5
#FTYPE:ANSI
#IDENTITY:31.05.2022
#DECIMAL:COMMA
#SEPARATOR:SEMICOLON
#MTYPE:DSC
#INSTRUMENT:NETZSCH STA 449F5
#PROJECT:ÑÂ×
#DATE/TIME:31.05.2022 10:59
#CORR. FILE:Êîððåêöèÿ 2 26 -1000 10 Ar (50 ml-min) .ngb-bs5
#TEMPCAL:TCALZERO.TCX
#SENSITIVITY:SENSZERO.EXX
#LABORATORY:108
#OPERATOR:Èáðàåâà
#REMARK:
#SAMPLE:Îòðóáè
#SAMPLE MASS /mg:5,02
#MATERIAL:
#REFERENCE:
#REFERENCE MASS /mg:0
#TYPE OF CRUCIBLE:Al2O3 85 µl, with lid
#SAMPLE CRUCIBLE MASS /mg:224,86
#REFERENCE CRUCIBLE MASS /mg:224,00
#PURGE 1 MFC:OXYGEN,252,5 ml/min
#PURGE 2 MFC:ARGON,240,3 ml/min
#PROTECTIVE MFC:ARGON,240,3 ml/min
#DSC RANGE /µV:5000
#TG RANGE /mg:35000
#TAU-R:---
#CORR. CODE:020
#EXO:+1
#RANGE:28°C/10,0(K/min)/1000°C
#SEGMENT:S1/1
#SEG. 1:28°C/10,0(K/min)/1000°C

##Temp./°C;Time/min;DSC/(uV/mg);Mass/%;QMID(s:1|m:16)/A;QMID(s:1|m:28)/A;QMID(s:1|m:44)/A;QMID(s:1|m:18)/A;QMID(s:1|m:2)/A;Sensit./(uV/mW)
 30,00000; 1,72132;5,197496e-02;99,83377;7,541967e-11;1,695753e-10;1,162417e-10;2,665195e-09;3,227623e-11;1,00000
 40,00000; 3,44663;     0,21353;99,67520;7,592193e-11;1,699670e-10;1,160803e-10;2,677320e-09;3,251175e-11;1,00000
 50,00000; 4,51158;     0,31034;99,58366;7,616611e-11;1,693511e-10;1,158321e-10;2,696306e-09;3,249277e-11;1,00000
 60,00000; 5,41361;     0,39443;99,43221;7,690297e-11;1,692719e-10;1,155602e-10;2,723751e-09;3,251722e-11;1,00000
 70,00000; 6,23272;     0,46123;99,18736;7,758279e-11;1,686547e-10;1,153438e-10;2,771784e-09;3,245677e-11;1,00000
 80,00000; 7,01071;     0,50031;98,83278;7,843894e-11;1,679295e-10;1,149737e-10;2,834529e-09;3,259883e-11;1,00000
 90,00000; 7,76665;     0,52297;98,36787;7,990172e-11;1,676200e-10;1,147918e-10;2,902384e-09;3,272127e-11;1,00000
100,00000; 8,51581;     0,56253;97,82695;8,134508e-11;1,673680e-10;1,151149e-10;2,959737e-09;3,296955e-11;1,00000
110,00000; 9,27471;     0,65795;97,31534;8,208683e-11;1,670437e-10;1,152775e-10;2,991424e-09;3,306402e-11;1,00000
120,00000;10,05134;     0,80257;96,85207;8,193166e-11;1,667576e-10;1,151601e-10;2,990656e-09;3,302246e-11;1,00000
130,00000;10,84575;     0,98055;96,50154;8,108456e-11;1,661386e-10;1,149560e-10;2,962779e-09;3,299032e-11;1,00000
140,00000;11,66080;     1,15534;96,28155;7,994882e-11;1,659456e-10;1,151930e-10;2,922175e-09;3,298158e-11;1,00000
150,00000;12,50240;     1,30839;96,10455;7,959361e-11;1,658387e-10;1,164116e-10;2,884534e-09;3,296056e-11;1,00000
160,00000;13,37540;     1,44325;95,96826;7,937845e-11;1,654183e-10;1,180434e-10;2,860771e-09;3,303682e-11;1,00000
170,00000;14,28150;     1,56748;95,81249;7,939193e-11;1,652383e-10;1,202960e-10;2,855579e-09;3,295319e-11;1,00000
180,00000;15,21630;     1,69038;95,58713;8,040647e-11;1,656182e-10;1,240517e-10;2,869438e-09;3,292718e-11;1,00000
190,00000;16,17232;     1,81760;95,24708;8,181361e-11;1,655711e-10;1,279501e-10;2,901398e-09;3,316517e-11;1,00000
200,00000;17,14804;     1,95237;94,73593;8,315658e-11;1,666504e-10;1,313663e-10;2,950612e-09;3,332991e-11;1,00000
210,00000;18,13979;     2,09628;93,92096;8,513677e-11;1,684340e-10;1,365516e-10;3,012740e-09;3,351292e-11;1,00000
220,00000;19,14223;     2,25729;92,79903;8,784684e-11;1,724409e-10;1,457189e-10;3,073362e-09;3,373076e-11;1,00000
230,00000;20,15199;     2,42563;91,63903;9,026998e-11;1,780760e-10;1,556512e-10;3,119428e-09;3,394584e-11;1,00000
240,00000;21,16616;     2,59541;90,39412;9,237954e-11;1,871721e-10;1,673962e-10;3,162735e-09;3,416917e-11;1,00000
250,00000;22,18134;     2,77792;88,90030;9,612659e-11;2,028279e-10;1,889790e-10;3,235726e-09;3,443307e-11;1,00000
260,00000;23,19613;     2,96773;86,69726;1,035377e-10;2,302860e-10;2,284937e-10;3,365301e-09;3,482321e-11;1,00000
270,00000;24,20911;     3,15663;83,49536;1,153934e-10;2,739399e-10;2,911288e-10;3,556461e-09;3,557353e-11;1,00000
280,00000;25,22176;     3,33768;78,87386;1,290377e-10;3,241079e-10;3,678611e-10;3,784770e-09;3,647619e-11;1,00000
290,00000;26,23504;     3,49236;72,89175;1,425079e-10;3,618730e-10;4,434839e-10;3,993294e-09;3,789986e-11;1,00000
300,00000;27,24761;     3,59813;66,21019;1,522624e-10;3,718790e-10;5,001155e-10;4,103973e-09;3,900000e-11;1,00000
310,00000;28,26047;     3,54699;60,53973;1,507992e-10;3,454947e-10;4,924180e-10;4,070143e-09;3,929193e-11;1,00000
320,00000;29,27336;     3,54038;56,22112;1,418425e-10;3,137676e-10;4,451936e-10;3,939926e-09;3,870832e-11;1,00000
330,00000;30,28525;     3,57969;52,45560;1,360723e-10;3,037745e-10;4,156986e-10;3,802756e-09;3,823504e-11;1,00000
340,00000;31,29503;     3,60937;49,15918;1,314895e-10;2,975137e-10;3,900661e-10;3,687383e-09;3,818885e-11;1,00000
350,00000;32,30564;     3,62048;46,85017;1,231386e-10;2,723383e-10;3,362093e-10;3,578399e-09;3,759829e-11;1,00000
360,00000;33,31561;     3,67253;45,23667;1,149988e-10;2,478897e-10;2,851087e-10;3,481688e-09;3,730060e-11;1,00000
370,00000;34,32357;     3,75163;43,85539;1,110327e-10;2,374708e-10;2,573697e-10;3,416667e-09;3,726599e-11;1,00000
380,00000;35,33200;     3,82992;42,54075;1,091288e-10;2,338807e-10;2,405344e-10;3,384088e-09;3,715843e-11;1,00000
390,00000;36,34002;     3,90862;41,23053;1,080879e-10;2,335755e-10;2,278419e-10;3,371575e-09;3,721850e-11;1,00000
400,00000;37,34755;     3,99896;39,93698;1,079066e-10;2,333642e-10;2,172392e-10;3,369343e-09;3,718268e-11;1,00000
410,00000;38,35426;     4,09466;38,65951;1,080728e-10;2,339271e-10;2,069848e-10;3,372481e-09;3,714099e-11;1,00000
420,00000;39,36111;     4,18328;37,46890;1,085902e-10;2,344658e-10;1,983577e-10;3,378077e-09;3,729441e-11;1,00000
430,00000;40,36729;     4,27521;36,34886;1,095686e-10;2,340867e-10;1,906447e-10;3,384036e-09;3,746188e-11;1,00000
440,00000;41,37198;     4,36874;35,34080;1,106060e-10;2,339864e-10;1,836477e-10;3,389567e-09;3,749159e-11;1,00000
450,00000;42,37783;     4,45406;34,42386;1,122443e-10;2,338120e-10;1,774523e-10;3,395326e-09;3,735501e-11;1,00000
460,00000;43,38247;     4,53178;33,60647;1,144075e-10;2,330903e-10;1,718350e-10;3,401760e-09;3,733084e-11;1,00000
470,00000;44,38668;     4,59436;32,97864;1,170024e-10;2,314130e-10;1,670864e-10;3,407875e-09;3,728648e-11;1,00000
480,00000;45,38931;     4,64853;32,41246;1,194322e-10;2,278774e-10;1,627994e-10;3,412962e-09;3,731058e-11;1,00000
490,00000;46,39209;     4,68027;32,00827;1,215518e-10;2,221701e-10;1,608115e-10;3,417784e-09;3,752724e-11;1,00000
500,00000;47,39339;     4,68677;31,65594;1,229613e-10;2,127381e-10;1,639931e-10;3,423014e-09;3,755961e-11;1,00000
510,00000;48,39344;     4,68159;31,34426;1,234449e-10;2,027120e-10;1,675478e-10;3,428619e-09;3,750494e-11;1,00000
520,00000;49,39592;     4,67800;31,12494;1,229641e-10;1,955739e-10;1,681945e-10;3,434641e-09;3,752024e-11;1,00000
530,00000;50,39747;     4,67165;30,84706;1,215815e-10;1,915523e-10;1,669579e-10;3,441270e-09;3,751058e-11;1,00000
540,00000;51,39786;     4,65425;30,66103;1,197862e-10;1,886770e-10;1,644156e-10;3,448623e-09;3,750937e-11;1,00000
550,00000;52,39753;     4,61686;30,47918;1,178747e-10;1,866441e-10;1,617678e-10;3,457236e-09;3,756048e-11;1,00000
560,00000;53,39728;     4,56482;30,33010;1,157292e-10;1,845718e-10;1,594759e-10;3,467844e-09;3,752553e-11;1,00000
570,00000;54,39683;     4,50679;30,19948;1,136518e-10;1,832999e-10;1,571855e-10;3,480209e-09;3,782642e-11;1,00000
580,00000;55,39732;     4,44940;30,02121;1,115000e-10;1,829026e-10;1,543421e-10;3,493477e-09;3,794544e-11;1,00000
590,00000;56,39716;     4,39783;29,93744;1,090916e-10;1,823106e-10;1,517489e-10;3,507369e-09;3,791665e-11;1,00000
600,00000;57,39705;     4,35096;29,76965;1,070963e-10;1,817925e-10;1,494534e-10;3,521605e-09;3,812274e-11;1,00000
610,00000;58,39684;     4,32093;29,70252;1,047002e-10;1,812370e-10;1,473091e-10;3,535634e-09;3,849619e-11;1,00000
620,00000;59,39670;     4,30848;29,55432;1,024266e-10;1,813596e-10;1,451562e-10;3,549624e-09;3,876741e-11;1,00000
630,00000;60,39684;     4,32411;29,46487;1,006203e-10;1,816940e-10;1,429501e-10;3,563902e-09;3,899948e-11;1,00000
640,00000;61,39720;     4,35900;29,39285;9,914885e-11;1,824267e-10;1,404824e-10;3,578828e-09;3,917584e-11;1,00000
650,00000;62,39710;     4,42117;29,28518;9,833861e-11;1,833251e-10;1,373432e-10;3,594881e-09;3,930450e-11;1,00000
660,00000;63,39824;     4,49692;29,22816;9,693620e-11;1,844131e-10;1,346163e-10;3,611125e-09;3,962771e-11;1,00000
670,00000;64,40049;     4,59238;29,15704;9,596379e-11;1,852461e-10;1,320560e-10;3,626111e-09;3,993783e-11;1,00000
680,00000;65,40312;     4,69906;29,03430;9,526285e-11;1,859619e-10;1,304656e-10;3,640336e-09;4,024820e-11;1,00000
690,00000;66,40445;     4,82147;29,02050;9,484967e-11;1,861984e-10;1,298741e-10;3,654732e-09;4,052808e-11;1,00000
700,00000;67,40670;     4,93843;28,90900;9,459382e-11;1,857927e-10;1,297881e-10;3,669011e-09;4,102312e-11;1,00000
710,00000;68,40997;     5,05789;28,89728;9,426158e-11;1,858595e-10;1,298737e-10;3,683076e-09;4,160308e-11;1,00000
720,00000;69,41305;     5,17512;28,83809;9,415064e-11;1,862314e-10;1,299220e-10;3,696892e-09;4,190953e-11;1,00000
730,00000;70,41555;     5,28473;28,76521;9,403522e-11;1,867224e-10;1,296940e-10;3,710233e-09;4,203555e-11;1,00000
740,00000;71,41868;     5,37672;28,72600;9,350168e-11;1,869263e-10;1,295870e-10;3,723465e-09;4,213396e-11;1,00000
750,00000;72,42044;     5,47011;28,64039;9,334649e-11;1,872287e-10;1,297482e-10;3,736969e-09;4,188319e-11;1,00000
760,00000;73,42343;     5,55519;28,59668;9,352922e-11;1,867541e-10;1,303798e-10;3,750593e-09;4,153296e-11;1,00000
770,00000;74,42585;     5,65146;28,54780;9,368948e-11;1,863444e-10;1,311342e-10;3,763891e-09;4,092758e-11;1,00000
780,00000;75,42785;     5,75922;28,53673;9,391783e-11;1,852770e-10;1,337071e-10;3,776561e-09;4,073285e-11;1,00000
790,00000;76,43007;     5,89305;28,49180;9,449864e-11;1,837475e-10;1,372970e-10;3,788952e-09;4,091186e-11;1,00000
800,00000;77,43364;     6,05054;28,41038;9,517004e-11;1,819733e-10;1,405860e-10;3,801296e-09;4,046934e-11;1,00000
810,00000;78,43738;     6,28010;28,36193;9,600935e-11;1,810394e-10;1,441256e-10;3,813114e-09;4,021544e-11;1,00000
820,00000;79,44094;     6,55319;28,32486;9,634276e-11;1,797876e-10;1,474337e-10;3,824438e-09;3,995318e-11;1,00000
830,00000;80,44367;     6,85821;28,27476;9,693742e-11;1,786240e-10;1,502519e-10;3,835825e-09;3,978928e-11;1,00000
840,00000;81,44471;     7,16613;28,20536;9,760022e-11;1,781467e-10;1,525009e-10;3,847516e-09;3,975706e-11;1,00000
850,00000;82,44205;     7,44109;28,14699;9,802564e-11;1,775290e-10;1,549911e-10;3,859736e-09;3,948685e-11;1,00000
860,00000;83,43750;     7,62685;28,10409;9,837472e-11;1,768795e-10;1,570496e-10;3,872462e-09;3,928400e-11;1,00000
870,00000;84,43118;     7,73851;28,02670;9,869809e-11;1,761698e-10;1,590943e-10;3,884826e-09;3,935589e-11;1,00000
880,00000;85,42401;     7,77984;27,97275;9,917989e-11;1,754125e-10;1,617346e-10;3,896556e-09;3,942497e-11;1,00000
890,00000;86,41601;     7,74657;27,89419;9,983835e-11;1,761253e-10;1,643224e-10;3,908636e-09;3,919497e-11;1,00000
900,00000;87,40911;     7,66474;27,86481;1,004577e-10;1,768230e-10;1,675035e-10;3,921596e-09;3,931682e-11;1,00000
910,00000;88,40262;     7,53351;27,67878;1,010120e-10;1,777892e-10;1,709818e-10;3,935138e-09;3,953382e-11;1,00000
920,00000;89,39545;     7,39778;27,65771;1,018545e-10;1,793831e-10;1,750352e-10;3,949175e-09;3,950472e-11;1,00000
930,00000;90,39032;     7,21409;27,53859;1,023824e-10;1,817210e-10;1,785457e-10;3,963398e-09;3,960925e-11;1,00000
940,00000;91,38576;     7,01984;27,40288;1,029078e-10;1,854788e-10;1,813423e-10;3,977068e-09;3,970228e-11;1,00000
950,00000;92,38192;     6,83707;27,27739;1,033078e-10;1,897287e-10;1,836410e-10;3,989736e-09;3,977613e-11;1,00000
960,00000;93,37858;     6,70188;27,14154;1,040331e-10;1,933267e-10;1,850138e-10;4,002027e-09;3,986943e-11;1,00000
970,00000;94,37528;     6,57641;26,99124;1,046794e-10;1,961520e-10;1,848539e-10;4,014796e-09;4,006147e-11;1,00000
980,00000;95,37413;     6,46924;26,83253;1,046035e-10;1,972437e-10;1,835753e-10;4,028005e-09;4,010525e-11;1,00000
990,00000;96,37230;     6,36861;26,71615;1,044140e-10;1,978832e-10;1,817915e-10;4,040542e-09;4,020435e-11;1,00000