File: data/data_piroliz_10/ExpDat_6.06.2022 Скорлупа  28-1000 10 Ar +MS SCB.txt
#EXPORTTYPE:DATA ALL
#FILE:6.06.2022 Ñêîðëóïà  28-1000 10 Ar +MS SCB.ngb-ds5
#FORMAT:NETZSCH5
#FTYPE:ANSI
#IDENTITY:06.06.2022
#DECIMAL:COMMA
#SEPARATOR:SEMICOLON
#MTYPE:DSC
#INSTRUMENT:NETZSCH STA 449F5
#PROJECT:ÑÂ×
#DATE/TIME:06.06.2022 12:03
#CORR. FILE:Êîððåêöèÿ 2 26 -1000 10 Ar (50 ml-min) .ngb-bs5
#TEMPCAL:TCALZERO.TCX
#SENSITIVITY:SENSZERO.EXX
#LABORATORY:108
#OPERATOR:Èáðàåâà
#REMARK:
#SAMPLE:Ñêîðëóïà
#SAMPLE MASS /mg:5,07
#MATERIAL:
#REFERENCE:
#REFERENCE MASS /mg:0
#TYPE OF CRUCIBLE:Al2O3 85 µl, with lid
#SAMPLE CRUCIBLE MASS /mg:225,84
#REFERENCE CRUCIBLE MASS /mg:224,00
#PURGE 1 MFC:OXYGEN,252,5 ml/min
#PURGE 2 MFC:ARGON,240,3 ml/min
#PROTECTIVE MFC:ARGON,240,3 ml/min
#DSC RANGE /µV:5000
#TG RANGE /mg:35000
#TAU-R:---
#CORR. CODE:020
#EXO:+1
#RANGE:28°C/10,0(K/min)/1000°C
#SEGMENT:S1/1
#SEG. 1:28°C/10,0(K/min)/1000°C

##Temp./°C;Time/min;DSC/(uV/mg);Mass/%;QMID(s:1|m:16)/A;QMID(s:1|m:28)/A;QMID(s:1|m:44)/A;QMID(s:1|m:18)/A;QMID(s:1|m:2)/A;Sensit./(uV/mW)
 30,00000; 1,51009;3,012022e-02;99,89042;3,689440e-10;4,503157e-10;7,068361e-10;1,453826e-08;4,981156e-11;1,00000
 40,00000; 3,40123;     0,18095;99,68372;3,693585e-10;4,507941e-10;7,038995e-10;1,461255e-08;4,968150e-11;1,00000
 50,00000; 4,48968;     0,26675;99,60566;3,703193e-10;4,499042e-10;7,002478e-10;1,465481e-08;4,986394e-11;1,00000
 60,00000; 5,40300;     0,34641;99,48855;3,703930e-10;4,488783e-10;6,956176e-10;1,468758e-08;5,000693e-11;1,00000
 70,00000; 6,22969;     0,41967;99,29191;3,706723e-10;4,469536e-10;6,902109e-10;1,473186e-08;5,013519e-11;1,00000
 80,00000; 7,01100;     0,47925;99,03941;3,708718e-10;4,448080e-10;6,848757e-10;1,477825e-08;5,014682e-11;1,00000
 90,00000; 7,77040;     0,52834;98,73609;3,711788e-10;4,421448e-10;6,792821e-10;1,482710e-08;4,998599e-11;1,00000
100,00000; 8,52219;     0,59501;98,41244;3,713656e-10;4,398542e-10;6,743076e-10;1,486549e-08;5,006217e-11;1,00000
110,00000; 9,28277;     0,69211;98,09015;3,712661e-10;4,384927e-10;6,696234e-10;1,487485e-08;5,014703e-11;1,00000
120,00000;10,06108;     0,81626;97,78965;3,701763e-10;4,367860e-10;6,644271e-10;1,486029e-08;5,014488e-11;1,00000
130,00000;10,85577;     0,96103;97,57267;3,689653e-10;4,346405e-10;6,593309e-10;1,482922e-08;5,010061e-11;1,00000
140,00000;11,67072;     1,10598;97,45835;3,682269e-10;4,326472e-10;6,546277e-10;1,478984e-08;4,999590e-11;1,00000
150,00000;12,51159;     1,23545;97,38967;3,671959e-10;4,306091e-10;6,497140e-10;1,475456e-08;4,994092e-11;1,00000
160,00000;13,38438;     1,35381;97,32319;3,662383e-10;4,290969e-10;6,450928e-10;1,473118e-08;4,999683e-11;1,00000
170,00000;14,28916;     1,46987;97,25850;3,660410e-10;4,274253e-10;6,428348e-10;1,471909e-08;4,992712e-11;1,00000
180,00000;15,22205;     1,59112;97,18199;3,657630e-10;4,258962e-10;6,402931e-10;1,471743e-08;5,004410e-11;1,00000
190,00000;16,17655;     1,71276;97,07681;3,647933e-10;4,244723e-10;6,368116e-10;1,471823e-08;5,018628e-11;1,00000
200,00000;17,15079;     1,84107;96,90928;3,642364e-10;4,220257e-10;6,325978e-10;1,472396e-08;5,031166e-11;1,00000
210,00000;18,14158;     1,97771;96,70972;3,646898e-10;4,198887e-10;6,289140e-10;1,473478e-08;5,025225e-11;1,00000
220,00000;19,14386;     2,12149;96,41586;3,648992e-10;4,194563e-10;6,271056e-10;1,474931e-08;5,014244e-11;1,00000
230,00000;20,15238;     2,27444;96,00560;3,655926e-10;4,189822e-10;6,285387e-10;1,478018e-08;5,036892e-11;1,00000
240,00000;21,16573;     2,43920;95,39204;3,667242e-10;4,198104e-10;6,340377e-10;1,483115e-08;5,078710e-11;1,00000
250,00000;22,18060;     2,62355;94,41570;3,689171e-10;4,242976e-10;6,474638e-10;1,489864e-08;5,117604e-11;1,00000
260,00000;23,19471;     2,83005;92,83382;3,734188e-10;4,351529e-10;6,758701e-10;1,500381e-08;5,169647e-11;1,00000
270,00000;24,20646;     3,03467;90,57844;3,798810e-10;4,545277e-10;7,163013e-10;1,513033e-08;5,214551e-11;1,00000
280,00000;25,22073;     3,19991;87,88747;3,848943e-10;4,777288e-10;7,459538e-10;1,522942e-08;5,266896e-11;1,00000
290,00000;26,23346;     3,34250;84,89908;3,871046e-10;4,941963e-10;7,606439e-10;1,528534e-08;5,333397e-11;1,00000
300,00000;27,24648;     3,46077;81,66107;3,882378e-10;5,062227e-10;7,708991e-10;1,533106e-08;5,351366e-11;1,00000
310,00000;28,25950;     3,55989;78,11711;3,908833e-10;5,185745e-10;7,834552e-10;1,538338e-08;5,377918e-11;1,00000
320,00000;29,27088;     3,64828;74,20813;3,933554e-10;5,338927e-10;7,975608e-10;1,543156e-08;5,421219e-11;1,00000
330,00000;30,28176;     3,71825;69,64849;3,973297e-10;5,604204e-10;8,240718e-10;1,551139e-08;5,454602e-11;1,00000
340,00000;31,29134;     3,78052;63,94867;4,056521e-10;6,097125e-10;8,767540e-10;1,566231e-08;5,558776e-11;1,00000
350,00000;32,30152;     3,83125;56,99084;4,164375e-10;6,663239e-10;9,429863e-10;1,586449e-08;5,702258e-11;1,00000
360,00000;33,31156;     3,81606;50,92807;4,152559e-10;6,488902e-10;9,278811e-10;1,585632e-08;5,744131e-11;1,00000
370,00000;34,32254;     3,80281;47,73696;3,970255e-10;5,466766e-10;7,931548e-10;1,552499e-08;5,567815e-11;1,00000
380,00000;35,33180;     3,87115;46,20816;3,828823e-10;4,753170e-10;6,861446e-10;1,523896e-08;5,411540e-11;1,00000
390,00000;36,33963;     3,97155;45,05646;3,805112e-10;4,536130e-10;6,446818e-10;1,512593e-08;5,354415e-11;1,00000
400,00000;37,34676;     4,08480;43,98144;3,839035e-10;4,477687e-10;6,266868e-10;1,508543e-08;5,331682e-11;1,00000
410,00000;38,35301;     4,19156;42,95717;3,873164e-10;4,461396e-10;6,135993e-10;1,506922e-08;5,316170e-11;1,00000
420,00000;39,35909;     4,28833;41,96787;3,902948e-10;4,452218e-10;6,031979e-10;1,506107e-08;5,321729e-11;1,00000
430,00000;40,36431;     4,37210;41,03047;3,908697e-10;4,443440e-10;5,932325e-10;1,505467e-08;5,326184e-11;1,00000
440,00000;41,36961;     4,44230;40,21605;3,883336e-10;4,432089e-10;5,818717e-10;1,503642e-08;5,294966e-11;1,00000
450,00000;42,37452;     4,50811;39,48766;3,833575e-10;4,404460e-10;5,717886e-10;1,501937e-08;5,277042e-11;1,00000
460,00000;43,37765;     4,55145;38,83439;3,795283e-10;4,349811e-10;5,673038e-10;1,499798e-08;5,259177e-11;1,00000
470,00000;44,38094;     4,57651;38,25716;3,779003e-10;4,253405e-10;5,699570e-10;1,498076e-08;5,263456e-11;1,00000
480,00000;45,38371;     4,63975;37,72790;3,776541e-10;4,161482e-10;5,711405e-10;1,496861e-08;5,252853e-11;1,00000
490,00000;46,38689;     4,71696;37,26748;3,781213e-10;4,089450e-10;5,684542e-10;1,495861e-08;5,242664e-11;1,00000
500,00000;47,38963;     4,78517;36,81795;3,784293e-10;4,035824e-10;5,654549e-10;1,494327e-08;5,267082e-11;1,00000
510,00000;48,39139;     4,83162;36,40227;3,783365e-10;3,990114e-10;5,625832e-10;1,492898e-08;5,267508e-11;1,00000
520,00000;49,39238;     4,86301;36,02829;3,785361e-10;3,927494e-10;5,611362e-10;1,491986e-08;5,257931e-11;1,00000
530,00000;50,39307;     4,88149;35,65946;3,783911e-10;3,858086e-10;5,581039e-10;1,491188e-08;5,271036e-11;1,00000
540,00000;51,39407;     4,89572;35,30535;3,771709e-10;3,810419e-10;5,508013e-10;1,490881e-08;5,266746e-11;1,00000
550,00000;52,39372;     4,92544;34,98914;3,764393e-10;3,781396e-10;5,433477e-10;1,490503e-08;5,265468e-11;1,00000
560,00000;53,39455;     4,97306;34,69697;3,746624e-10;3,761661e-10;5,363503e-10;1,489854e-08;5,280101e-11;1,00000
570,00000;54,39600;     5,04595;34,40433;3,732466e-10;3,745812e-10;5,303122e-10;1,489895e-08;5,285203e-11;1,00000
580,00000;55,39823;     5,16585;34,13038;3,715627e-10;3,728763e-10;5,239404e-10;1,488953e-08;5,304098e-11;1,00000
590,00000;56,40123;     5,31956;33,88240;3,698438e-10;3,717277e-10;5,174011e-10;1,489062e-08;5,313669e-11;1,00000
600,00000;57,40357;     5,49997;33,65000;3,676184e-10;3,709715e-10;5,119759e-10;1,489325e-08;5,351730e-11;1,00000
610,00000;58,40697;     5,71258;33,41578;3,643143e-10;3,700763e-10;5,049180e-10;1,489301e-08;5,383255e-11;1,00000
620,00000;59,40930;     5,91100;33,21575;3,616988e-10;3,699291e-10;4,965034e-10;1,489647e-08;5,377487e-11;1,00000
630,00000;60,41256;     6,11095;33,04287;3,586387e-10;3,709108e-10;4,881358e-10;1,490126e-08;5,417854e-11;1,00000
640,00000;61,41345;     6,31108;32,88708;3,556434e-10;3,718353e-10;4,788694e-10;1,490250e-08;5,465217e-11;1,00000
650,00000;62,41482;     6,50351;32,74480;3,532639e-10;3,737684e-10;4,695184e-10;1,490623e-08;5,481846e-11;1,00000
660,00000;63,41695;     6,69961;32,61127;3,511057e-10;3,768717e-10;4,594511e-10;1,490964e-08;5,523551e-11;1,00000
670,00000;64,41818;     6,87877;32,48206;3,482300e-10;3,779912e-10;4,513845e-10;1,490746e-08;5,604272e-11;1,00000
680,00000;65,41962;     7,05000;32,37563;3,463742e-10;3,774858e-10;4,467124e-10;1,491091e-08;5,708975e-11;1,00000
690,00000;66,42127;     7,23373;32,28132;3,451492e-10;3,768204e-10;4,435491e-10;1,491363e-08;5,833929e-11;1,00000
700,00000;67,42214;     7,41215;32,16622;3,441230e-10;3,754604e-10;4,409103e-10;1,490870e-08;5,972108e-11;1,00000
710,00000;68,42307;     7,56967;32,07053;3,433369e-10;3,747987e-10;4,386194e-10;1,490571e-08;6,088736e-11;1,00000
720,00000;69,42283;     7,70717;31,96660;3,421684e-10;3,741230e-10;4,364774e-10;1,490770e-08;6,199631e-11;1,00000
730,00000;70,42372;     7,82908;31,86809;3,408002e-10;3,731748e-10;4,341962e-10;1,490881e-08;6,287044e-11;1,00000
740,00000;71,42354;     7,95203;31,75966;3,399196e-10;3,715840e-10;4,322499e-10;1,490463e-08;6,358012e-11;1,00000
750,00000;72,42329;     8,06714;31,66681;3,398802e-10;3,696115e-10;4,308382e-10;1,490752e-08;6,352480e-11;1,00000
760,00000;73,42261;     8,18456;31,61261;3,396605e-10;3,674189e-10;4,298932e-10;1,490709e-08;6,285175e-11;1,00000
770,00000;74,42314;     8,29889;31,53390;3,395326e-10;3,650328e-10;4,287065e-10;1,490531e-08;6,196707e-11;1,00000
780,00000;75,42286;     8,40455;31,48652;3,390786e-10;3,625640e-10;4,279909e-10;1,490379e-08;6,098944e-11;1,00000
790,00000;76,42199;     8,52275;31,43196;3,385682e-10;3,594425e-10;4,268225e-10;1,489720e-08;5,970530e-11;1,00000
800,00000;77,42236;     8,62478;31,34652;3,385420e-10;3,569147e-10;4,261701e-10;1,489593e-08;5,805401e-11;1,00000
810,00000;78,42246;     8,73626;31,31145;3,384122e-10;3,544905e-10;4,269579e-10;1,489276e-08;5,651427e-11;1,00000
820,00000;79,42384;     8,87105;31,27398;3,383271e-10;3,506843e-10;4,289642e-10;1,488583e-08;5,573479e-11;1,00000
830,00000;80,42583;     9,07909;31,24295;3,379170e-10;3,470143e-10;4,296979e-10;1,487711e-08;5,553390e-11;1,00000
840,00000;81,42759;     9,29245;31,20063;3,380480e-10;3,449839e-10;4,292065e-10;1,486818e-08;5,508647e-11;1,00000
850,00000;82,42821;     9,46406;31,17060;3,380683e-10;3,429194e-10;4,280340e-10;1,486351e-08;5,466868e-11;1,00000
860,00000;83,42625;     9,54919;31,13470;3,373988e-10;3,415863e-10;4,268215e-10;1,485829e-08;5,452451e-11;1,00000
870,00000;84,42317;     9,58431;31,09928;3,374051e-10;3,404008e-10;4,258109e-10;1,485083e-08;5,462841e-11;1,00000
880,00000;85,41646;     9,52173;31,07065;3,376070e-10;3,397160e-10;4,251704e-10;1,483924e-08;5,436632e-11;1,00000
890,00000;86,41020;     9,37304;31,04137;3,376662e-10;3,392892e-10;4,243730e-10;1,483079e-08;5,401406e-11;1,00000
900,00000;87,40526;     9,14870;31,04963;3,374344e-10;3,387623e-10;4,229100e-10;1,482491e-08;5,417837e-11;1,00000
910,00000;88,39979;     8,87001;31,00490;3,371613e-10;3,382212e-10;4,213223e-10;1,481775e-08;5,414020e-11;1,00000
920,00000;89,39553;     8,54037;30,99092;3,365018e-10;3,372491e-10;4,201023e-10;1,480806e-08;5,419554e-11;1,00000
930,00000;90,39088;     8,20057;30,95944;3,358189e-10;3,365700e-10;4,185831e-10;1,480017e-08;5,421012e-11;1,00000
940,00000;91,38678;     7,85865;30,93439;3,363018e-10;3,364130e-10;4,174257e-10;1,479757e-08;5,425835e-11;1,00000
950,00000;92,38232;     7,54941;30,91584;3,364531e-10;3,359779e-10;4,163150e-10;1,478568e-08;5,438055e-11;1,00000
960,00000;93,38009;     7,28689;30,88635;3,359727e-10;3,352583e-10;4,148660e-10;1,477392e-08;5,412012e-11;1,00000
970,00000;94,37743;     7,05691;30,86714;3,359796e-10;3,346488e-10;4,133409e-10;1,476752e-08;5,417841e-11;1,00000
980,00000;95,37582;     6,84964;30,84634;3,356794e-10;3,347066e-10;4,120180e-10;1,475752e-08;5,409829e-11;1,00000
990,00000;96,37249;     6,65490;30,83401;3,356940e-10;3,341447e-10;4,100618e-10;1,475036e-08;5,408527e-11;1,00000