File: data/data_piroliz_20/ExpDat_31.05.2022 Отруби  27-1000 10 Ar +MS SCB [1wZ7JS].txt
#EXPORTTYPE:DATA ALL
#FILE:31.05.2022 Îòðóáè  27-1000 10 Ar +MS SCB .ngb-ds5
#FORMAT:NETZSCH5
#FTYPE:ANSI
#IDENTITY:31.05.2022
#DECIMAL:COMMA
#SEPARATOR:SEMICOLON
#MTYPE:DSC
#INSTRUMENT:NETZSCH STA 449F5
#PROJECT:ÑÂ×
#DATE/TIME:31.05.2022 10:59
#CORR. FILE:Êîððåêöèÿ 2 26 -1000 10 Ar (50 ml-min) .ngb-bs5
#TEMPCAL:TCALZERO.TCX
#SENSITIVITY:SENSZERO.EXX
#LABORATORY:108
#OPERATOR:Èáðàåâà
#REMARK:
#SAMPLE:Îòðóáè
#SAMPLE MASS /mg:5,02
#MATERIAL:
#REFERENCE:
#REFERENCE MASS /mg:0
#TYPE OF CRUCIBLE:Al2O3 85 µl, with lid
#SAMPLE CRUCIBLE MASS /mg:224,86
#REFERENCE CRUCIBLE MASS /mg:224,00
#PURGE 1 MFC:OXYGEN,252,5 ml/min
#PURGE 2 MFC:ARGON,240,3 ml/min
#PROTECTIVE MFC:ARGON,240,3 ml/min
#DSC RANGE /µV:5000
#TG RANGE /mg:35000
#TAU-R:---
#CORR. CODE:020
#EXO:+1
#RANGE:28°C/10,0(K/min)/1000°C
#SEGMENT:S1/1
#SEG. 1:28°C/10,0(K/min)/1000°C

##Temp./°C;Time/min;DSC/(uV/mg);Mass/%;QMID(s:1|m:16)/A;QMID(s:1|m:28)/A;QMID(s:1|m:44)/A;QMID(s:1|m:18)/A;QMID(s:1|m:2)/A;Sensit./(uV/mW)
 30,00000; 1,72132;5,197496e-02;99,83377;7,541967e-11;1,695753e-10;1,162417e-10;2,665195e-09;3,227623e-11;1,00000
 50,00000; 4,51158;     0,31034;99,58366;7,616611e-11;1,693511e-10;1,158321e-10;2,696306e-09;3,249277e-11;1,00000
 70,00000; 6,23272;     0,46123;99,18736;7,758279e-11;1,686547e-10;1,153438e-10;2,771784e-09;3,245677e-11;1,00000
 90,00000; 7,76665;     0,52297;98,36787;7,990172e-11;1,676200e-10;1,147918e-10;2,902384e-09;3,272127e-11;1,00000
110,00000; 9,27471;     0,65795;97,31534;8,208683e-11;1,670437e-10;1,152775e-10;2,991424e-09;3,306402e-11;1,00000
130,00000;10,84575;     0,98055;96,50154;8,108456e-11;1,661386e-10;1,149560e-10;2,962779e-09;3,299032e-11;1,00000
150,00000;12,50240;     1,30839;96,10455;7,959361e-11;1,658387e-10;1,164116e-10;2,884534e-09;3,296056e-11;1,00000
170,00000;14,28150;     1,56748;95,81249;7,939193e-11;1,652383e-10;1,202960e-10;2,855579e-09;3,295319e-11;1,00000
190,00000;16,17232;     1,81760;95,24708;8,181361e-11;1,655711e-10;1,279501e-10;2,901398e-09;3,316517e-11;1,00000
210,00000;18,13979;     2,09628;93,92096;8,513677e-11;1,684340e-10;1,365516e-10;3,012740e-09;3,351292e-11;1,00000
230,00000;20,15199;     2,42563;91,63903;9,026998e-11;1,780760e-10;1,556512e-10;3,119428e-09;3,394584e-11;1,00000
250,00000;22,18134;     2,77792;88,90030;9,612659e-11;2,028279e-10;1,889790e-10;3,235726e-09;3,443307e-11;1,00000
270,00000;24,20911;     3,15663;83,49536;1,153934e-10;2,739399e-10;2,911288e-10;3,556461e-09;3,557353e-11;1,00000
290,00000;26,23504;     3,49236;72,89175;1,425079e-10;3,618730e-10;4,434839e-10;3,993294e-09;3,789986e-11;1,00000
310,00000;28,26047;     3,54699;60,53973;1,507992e-10;3,454947e-10;4,924180e-10;4,070143e-09;3,929193e-11;1,00000
330,00000;30,28525;     3,57969;52,45560;1,360723e-10;3,037745e-10;4,156986e-10;3,802756e-09;3,823504e-11;1,00000
350,00000;32,30564;     3,62048;46,85017;1,231386e-10;2,723383e-10;3,362093e-10;3,578399e-09;3,759829e-11;1,00000
370,00000;34,32357;     3,75163;43,85539;1,110327e-10;2,374708e-10;2,573697e-10;3,416667e-09;3,726599e-11;1,00000
390,00000;36,34002;     3,90862;41,23053;1,080879e-10;2,335755e-10;2,278419e-10;3,371575e-09;3,721850e-11;1,00000
410,00000;38,35426;     4,09466;38,65951;1,080728e-10;2,339271e-10;2,069848e-10;3,372481e-09;3,714099e-11;1,00000
430,00000;40,36729;     4,27521;36,34886;1,095686e-10;2,340867e-10;1,906447e-10;3,384036e-09;3,746188e-11;1,00000
450,00000;42,37783;     4,45406;34,42386;1,122443e-10;2,338120e-10;1,774523e-10;3,395326e-09;3,735501e-11;1,00000
470,00000;44,38668;     4,59436;32,97864;1,170024e-10;2,314130e-10;1,670864e-10;3,407875e-09;3,728648e-11;1,00000
490,00000;46,39209;     4,68027;32,00827;1,215518e-10;2,221701e-10;1,608115e-10;3,417784e-09;3,752724e-11;1,00000
510,00000;48,39344;     4,68159;31,34426;1,234449e-10;2,027120e-10;1,675478e-10;3,428619e-09;3,750494e-11;1,00000
530,00000;50,39747;     4,67165;30,84706;1,215815e-10;1,915523e-10;1,669579e-10;3,441270e-09;3,751058e-11;1,00000
550,00000;52,39753;     4,61686;30,47918;1,178747e-10;1,866441e-10;1,617678e-10;3,457236e-09;3,756048e-11;1,00000
570,00000;54,39683;     4,50679;30,19948;1,136518e-10;1,832999e-10;1,571855e-10;3,480209e-09;3,782642e-11;1,00000
590,00000;56,39716;     4,39783;29,93744;1,090916e-10;1,823106e-10;1,517489e-10;3,507369e-09;3,791665e-11;1,00000
610,00000;58,39684;     4,32093;29,70252;1,047002e-10;1,812370e-10;1,473091e-10;3,535634e-09;3,849619e-11;1,00000
630,00000;60,39684;     4,32411;29,46487;1,006203e-10;1,816940e-10;1,429501e-10;3,563902e-09;3,899948e-11;1,00000
650,00000;62,39710;     4,42117;29,28518;9,833861e-11;1,833251e-10;1,373432e-10;3,594881e-09;3,930450e-11;1,00000
670,00000;64,40049;     4,59238;29,15704;9,596379e-11;1,852461e-10;1,320560e-10;3,626111e-09;3,993783e-11;1,00000
690,00000;66,40445;     4,82147;29,02050;9,484967e-11;1,861984e-10;1,298741e-10;3,654732e-09;4,052808e-11;1,00000
710,00000;68,40997;     5,05789;28,89728;9,426158e-11;1,858595e-10;1,298737e-10;3,683076e-09;4,160308e-11;1,00000
730,00000;70,41555;     5,28473;28,76521;9,403522e-11;1,867224e-10;1,296940e-10;3,710233e-09;4,203555e-11;1,00000
750,00000;72,42044;     5,47011;28,64039;9,334649e-11;1,872287e-10;1,297482e-10;3,736969e-09;4,188319e-11;1,00000
770,00000;74,42585;     5,65146;28,54780;9,368948e-11;1,863444e-10;1,311342e-10;3,763891e-09;4,092758e-11;1,00000
790,00000;76,43007;     5,89305;28,49180;9,449864e-11;1,837475e-10;1,372970e-10;3,788952e-09;4,091186e-11;1,00000
810,00000;78,43738;     6,28010;28,36193;9,600935e-11;1,810394e-10;1,441256e-10;3,813114e-09;4,021544e-11;1,00000
830,00000;80,44367;     6,85821;28,27476;9,693742e-11;1,786240e-10;1,502519e-10;3,835825e-09;3,978928e-11;1,00000
850,00000;82,44205;     7,44109;28,14699;9,802564e-11;1,775290e-10;1,549911e-10;3,859736e-09;3,948685e-11;1,00000
870,00000;84,43118;     7,73851;28,02670;9,869809e-11;1,761698e-10;1,590943e-10;3,884826e-09;3,935589e-11;1,00000
890,00000;86,41601;     7,74657;27,89419;9,983835e-11;1,761253e-10;1,643224e-10;3,908636e-09;3,919497e-11;1,00000
910,00000;88,40262;     7,53351;27,67878;1,010120e-10;1,777892e-10;1,709818e-10;3,935138e-09;3,953382e-11;1,00000
930,00000;90,39032;     7,21409;27,53859;1,023824e-10;1,817210e-10;1,785457e-10;3,963398e-09;3,960925e-11;1,00000
950,00000;92,38192;     6,83707;27,27739;1,033078e-10;1,897287e-10;1,836410e-10;3,989736e-09;3,977613e-11;1,00000
970,00000;94,37528;     6,57641;26,99124;1,046794e-10;1,961520e-10;1,848539e-10;4,014796e-09;4,006147e-11;1,00000
990,00000;96,37230;     6,36861;26,71615;1,044140e-10;1,978832e-10;1,817915e-10;4,040542e-09;4,020435e-11;1,00000